<?xml version="1.0" encoding="UTF-8"?>
<!-- Generated by org.testng.reporters.JUnitReportReporter -->
<testsuite hostname="IN-komehta-W1" failures="1" tests="4" name="boonSupplyTests.CreateFundraiserTest" time="170.320" errors="0" timestamp="2019-11-05T21:28:46 IST" skipped="0">
  <testcase classname="boonSupplyTests.CreateFundraiserTest" name="StartNewFundRaiserWithNewUser" time="38.769">
    <failure message="There is an Exception. Please check the functionality manually." type="java.lang.AssertionError">
      <![CDATA[java.lang.AssertionError: There is an Exception. Please check the functionality manually.
at org.testng.Assert.fail(Assert.java:97)
at boonSupplyTests.CreateFundraiserTest.StartNewFundRaiserWithNewUser(CreateFundraiserTest.java:63)
at java.base/jdk.internal.reflect.NativeMethodAccessorImpl.invoke0(Native Method)
at java.base/jdk.internal.reflect.NativeMethodAccessorImpl.invoke(NativeMethodAccessorImpl.java:62)
at java.base/jdk.internal.reflect.DelegatingMethodAccessorImpl.invoke(DelegatingMethodAccessorImpl.java:43)
at java.base/java.lang.reflect.Method.invoke(Method.java:567)
at org.testng.internal.MethodInvocationHelper.invokeMethod(MethodInvocationHelper.java:133)
at org.testng.internal.TestInvoker.invokeMethod(TestInvoker.java:584)
at org.testng.internal.TestInvoker.invokeTestMethod(TestInvoker.java:172)
at org.testng.internal.MethodRunner.runInSequence(MethodRunner.java:46)
at org.testng.internal.TestInvoker$MethodInvocationAgent.invoke(TestInvoker.java:804)
at org.testng.internal.TestInvoker.invokeTestMethods(TestInvoker.java:145)
at org.testng.internal.TestMethodWorker.invokeTestMethods(TestMethodWorker.java:146)
at org.testng.internal.TestMethodWorker.run(TestMethodWorker.java:128)
at java.base/java.util.ArrayList.forEach(ArrayList.java:1540)
at org.testng.TestRunner.privateRun(TestRunner.java:770)
at org.testng.TestRunner.run(TestRunner.java:591)
at org.testng.SuiteRunner.runTest(SuiteRunner.java:402)
at org.testng.SuiteRunner.runSequentially(SuiteRunner.java:396)
at org.testng.SuiteRunner.privateRun(SuiteRunner.java:355)
at org.testng.SuiteRunner.run(SuiteRunner.java:304)
at org.testng.SuiteRunnerWorker.runSuite(SuiteRunnerWorker.java:53)
at org.testng.SuiteRunnerWorker.run(SuiteRunnerWorker.java:96)
at org.testng.TestNG.runSuitesSequentially(TestNG.java:1180)
at org.testng.TestNG.runSuitesLocally(TestNG.java:1102)
at org.testng.TestNG.runSuites(TestNG.java:1032)
at org.testng.TestNG.run(TestNG.java:1000)
at org.testng.remote.AbstractRemoteTestNG.run(AbstractRemoteTestNG.java:115)
at org.testng.remote.RemoteTestNG.initAndRun(RemoteTestNG.java:251)
at org.testng.remote.RemoteTestNG.main(RemoteTestNG.java:77)
]]>
    </failure>
  </testcase> <!-- StartNewFundRaiserWithNewUser -->
  <testcase classname="boonSupplyTests.CreateFundraiserTest" name="StartNewFundRaiserWithNewUser" time="37.488"/>
  <testcase classname="boonSupplyTests.CreateFundraiserTest" name="StartNewFundRaiserWithNewUser" time="46.750"/>
  <testcase classname="boonSupplyTests.CreateFundraiserTest" name="StartNewFundRaiserWithNewUser" time="47.313"/>
</testsuite> <!-- boonSupplyTests.CreateFundraiserTest -->
